{"prompt":"<|begin_of_text|><|start_header_id|>user<|end_header_id|>\n\nCan you expand this test for each case, to test elements_of wrapping multiple uses of elements_of and normal value yield in the same generator, for a total generator depth of 3?\n\n**tests/test_generator.cpp**\n```\n#include <zinc/common.hpp>\n\n#include <iostream>\n#include <stdexcept>\n#include <unordered_set>\n\nusing namespace zinc;\n\nstruct IntP\n{\n    static size_t next_id;\n    static std::unordered_set<size_t> leaked_ids;\n\n    IntP(int i)\n    : storage(new int(i))\n    , id(next_id ++)\n    { leaked_ids.insert(id); }\n\n    IntP(IntP const & other) noexcept\n    : storage(nullptr), id(~0)\n    { *this = other; }\n\n    IntP(IntP && other) noexcept\n    : storage(nullptr), id(~0)\n    { *this = std::move(other); }\n\n    ~IntP() noexcept\n    { clear(); }\n\n    IntP& operator=(IntP const & other) noexcept\n    {\n        clear();\n        if (other.storage == nullptr) {\n            storage = nullptr;\n        } else {\n            storage = new int((int)other);\n            id = next_id ++;\n            leaked_ids.insert(id);\n        }\n        return *this;\n    }\n\n    IntP& operator=(IntP && other) noexcept\n    {\n        clear();\n        storage = other.storage;\n        id = other.id;\n        other.clear_();\n        return *this;\n    }\n\n    operator int() const noexcept\n    { return *storage; }\n\n    void clear() noexcept\n    {\n        if (storage != nullptr) {\n            delete storage;\n            leaked_ids.erase(id);\n            clear_();\n        }\n    }\n\n    void clear_() noexcept\n    {\n        storage = nullptr;\n        id = ~0;\n    }\n\n    int* storage;\n    size_t id;\n};\nsize_t IntP::next_id = 0;\nstd::unordered_set<size_t> IntP::leaked_ids{};\n\ngenerator<IntP> iterates_normally()\n{\n    co_yield 1;\n    co_yield 2;\n    co_yield 3;\n}\n\ngenerator<IntP> throws_initially()\n{\n    throw std::runtime_error(\"initial exception\");\n    co_yield 4;\n}\n\ngenerator<IntP> throws_later()\n{\n    co_yield 5;\n    throw std::runtime_error(\"later exception\");\n}\n\ngenerator<IntP> empty_sequence()\n{\n    co_return;\n}\n\ngenerator<IntP> elements_of(generator<IntP>(gen)())\n{\n    co_yield ranges::elements_of(gen());\n}\n\nint main()\n{\n    int i;\n\n    i = 0;\n    for (int i_ : iterates_normally()) {\n        i += i_;\n    }\n    if (i != 6) {\n        throw std::logic_error(\"normal iteration test did not iterate expected value\");\n    }\n    std::cerr << \"normal iteration test passed\" << std::endl;\n\n    if (!IntP::leaked_ids.empty()) {\n        throw std::logic_error(\"yielded values were leaked\");\n    }\n    std::cerr << \"yielded value leak test passed\" << std::endl;\n\n    i = 0;\n    for (int i_ : iterates_normally()) {\n        i += i_;\n        break;\n    }\n    if (i != 1) {\n        throw std::logic_error(\"interrupted iteration test did not iterate expected value\");\n    }\n    std::cerr << \"interrupted iteration test passed\" << std::endl;\n\n    try {\n        i = 0;\n        for (int i_ : throws_later()) {\n            i += i_;\n        }\n        throw std::logic_error(\"generator iteration exception never thrown\");\n    } catch(std::runtime_error&) {\n        if (i != 5) {\n            throw std::logic_error(\"generator iteration exception test did not iterate expected value\");\n        }\n        std::cerr << \"generator iteration exception test passed\" << std::endl;\n    }\n\n    try {\n        i = 0;\n        for (int i_ : throws_initially()) {\n            i += i_;\n        }\n        throw std::logic_error(\"generator initial exception never thrown\");\n    } catch(std::runtime_error&) {\n        if (i != 0) {\n            throw std::logic_error(\"generator initial exception iterated a value when it should not have\");\n        }\n        std::cerr << \"generator initial exception test passed\" << std::endl;\n    }\n\n    if (!IntP::leaked_ids.empty()) {\n        throw std::logic_error(\"yielded values were leaked\");\n    }\n    std::cerr << \"yielded value leak test passed\" << std::endl;\n\n    i = 0;\n    for (int i_ : elements_of(iterates_normally)) {\n        i += i_;\n    }\n    if (i != 6) {\n        throw std::logic_error(\"normal elements_of test did not iterate expected value\");\n    }\n    std::cerr << \"normal elements_of test passed\" << std::endl;\n\n    i = 0;\n    for (int i_ : elements_of(iterates_normally)) {\n        i += i_;\n        break;\n    }\n    if (i != 1) {\n        throw std::logic_error(\"interrupted elements_of test did not iterate expected value\");\n    }\n    std::cerr << \"interrupted elements_of test passed\" << std::endl;\n\n    try {\n        i = 0;\n        for (int i_ : elements_of(throws_later)) {\n            i += i_;\n        }\n        throw std::logic_error(\"elements_of iteration exception never thrown\");\n    } catch(std::runtime_error&) {\n        if (i != 5) {\n            throw std::logic_error(\"elements_of iteration exception test did not iterate expected value\");\n        }\n        std::cerr << \"elements_of iteration exception test passed\" << std::endl;\n    }\n\n    try {\n        i = 0;\n        for (int i_ : elements_of(throws_initially)) {\n            i += i_;\n        }\n        throw std::logic_error(\"elements_of initial exception never thrown\");\n    } catch(std::runtime_error&) {\n        if (i != 0) {\n            throw std::logic_error(\"elements_of initial exception iterated a value when it should not have\");\n        }\n        std::cerr << \"elements_of initial exception test passed\" << std::endl;\n    }\n\n    // Test 0-length sequence\n    for ([[maybe_unused]]int i_ : empty_sequence()) {\n        throw std::logic_error(\"empty sequence test iterated a value\");\n    }\n    std::cerr << \"empty sequence test passed\" << std::endl;\n\n    // Test elements_of with 0-length sequence\n    for ([[maybe_unused]]int i_ : elements_of(empty_sequence)) {\n        throw std::logic_error(\"elements_of empty sequence test iterated a value\");\n    }\n    std::cerr << \"elements_of empty sequence test passed\" << std::endl;\n\n    if (!IntP::leaked_ids.empty()) {\n        throw std::logic_error(\"yielded values were leaked\");\n    }\n    std::cerr << \"yielded value leak test passed\" << std::endl;\n\n    return 0;\n}\n\n```<|eot_id|><|start_header_id|>assistant<|end_header_id|>\n\n","ts":1.738639067158E9}
{"completion":"To expand the test for each case, to test `elements_of` wrapping multiple uses of `elements_of` and normal value yield in the same generator, for a total generator depth of 3, you can add the following test cases:\n\n```cpp\ngenerator<IntP> elements_of_elements_of(generator<IntP>(gen)())\n{\n    co_yield ranges::elements_of(elements_of(gen()));\n}\n\ngenerator<IntP> elements_of_elements_of_elements_of(generator<IntP>(gen)())\n{\n    co_yield ranges::elements_of(elements_of_elements_of(gen()));\n}\n\n// ...\n\ni = 0;\nfor (int i_ : elements_of_elements_of(iterates_normally)) {\n    i += i_;\n}\nif (i != 6) {\n    throw std::logic_error(\"normal elements_of elements_of test did not iterate expected value\");\n}\nstd::cerr << \"normal elements_of elements_of test passed\" << std::endl;\n\ni = 0;\nfor (int i_ : elements_of_elements_of(iterates_normally)) {\n    i += i_;\n    break;\n}\nif (i != 1) {\n    throw std::logic_error(\"interrupted elements_of elements_of test did not iterate expected value\");\n}\nstd::cerr << \"interrupted elements_of elements_of test passed\" << std::endl;\n\ntry {\n    i = 0;\n    for (int i_ : elements_of_elements_of(throws_later)) {\n        i += i_;\n    }\n    throw std::logic_error(\"elements_of elements_of iteration exception never thrown\");\n} catch(std::runtime_error&) {\n    if (i != 5) {\n        throw std::logic_error(\"elements_of elements_of iteration exception test did not iterate expected value\");\n    }\n    std::cerr << \"elements_of elements_of iteration exception test passed\" << std::endl;\n}\n\ntry {\n    i = 0;\n    for (int i_ : elements_of_elements_of(throws_initially)) {\n        i += i_;\n    }\n    throw std::logic_error(\"elements_of elements_of initial exception never thrown\");\n} catch(std::runtime_error&) {\n    if (i != 0) {\n        throw std::logic_error(\"elements_of elements_of initial exception iterated a value when it should not have\");\n    }\n    std::cerr << \"elements_of elements_of initial exception test passed\" << std::endl;\n}\n\n// Test elements_of elements_of with 0-length sequence\nfor ([[maybe_unused]]int i_ : elements_of_elements_of(empty_sequence)) {\n    throw std::logic_error(\"elements_of elements_of empty sequence test iterated a value\");\n}\nstd::cerr << \"elements_of elements_of empty sequence test passed\" << std::endl;\n\n// ...\n\ni = 0;\nfor (int i_ : elements_of_elements_of_elements_of(iterates_normally)) {\n    i += i_;\n}\nif (i != 6) {\n    throw std::logic_error(\"normal elements_of elements_of elements_of test did not iterate expected value\");\n}\nstd::cerr << \"normal elements_of elements_of elements_of test passed\" << std::endl;\n\ni = 0;\nfor (int i_ : elements_of_elements_of_elements_of(iterates_normally)) {\n    i += i_;\n    break;\n}\nif (i != 1) {\n    throw std::logic_error(\"interrupted elements_of elements_of elements_of test did not iterate expected value\");\n}\nstd::cerr << \"interrupted elements_of elements_of elements_of test passed\" << std::endl;\n\ntry {\n    i = 0;\n    for (int i_ : elements_of_elements_of_elements_of(throws_later)) {\n        i += i_;\n    }\n    throw std::logic_error(\"elements_of elements_of elements_of iteration exception never thrown\");\n} catch(std::runtime_error&) {\n    if (i != 5) {\n        throw std::logic_error(\"elements_of elements_of elements_of iteration exception test did not iterate expected value\");\n    }\n    std::cerr << \"elements_of elements_of elements_of iteration exception test passed\" << std::endl;\n}\n\ntry {\n    i = 0;\n    for (int i_ : elements_of_elements_of_elements_of(throws_initially)) {\n        i += i_;\n    }\n    throw std::logic_error(\"elements_of elements_of elements_of initial exception never thrown\");\n} catch(std::runtime_error&) {\n    if (i != 0) {\n        throw std::logic_error(\"elements_of elements_of elements_of initial exception iterated a value when it should not have\");\n    }\n    std::cerr << \"elements_of elements_of elements_of initial exception test passed\" << std::endl;\n}\n\n// Test elements_of elements_of elements_of with 0-length sequence\nfor ([[maybe_unused]]int i_ : elements_of_elements_of_elements_of(empty_sequence)) {\n    throw std::logic_error(\"elements_of elements_of elements_of empty sequence test iterated a value\");\n}\nstd::cerr << \"elements_of elements_of elements_of empty sequence test passed\" << std::endl;\n```\n\nNote that I've added new test cases for `elements_of_elements_of` and `elements_of_elements_of_elements_of` with the same test logic as the original `elements_of` test cases. I've also added new generator functions `elements_of_elements_of` and `elements_of_elements_of_elements_of` to wrap the original generator functions with multiple layers of `elements_of`.","ts":1.738639092904E9}
